Workbook

Sheet BD
A1: EIXO | B1: ITEM | C1: Art | D1: REQUISITO | E1: Descrição | F1: Ponto Aplicáveis 2026 | G1: Pontos Recebidos 2026 | H1: Performance | I1: Responsável CEIInGov | J1: Coordenador Executivo | K1: Setor Executor | L1: Passível de Esforço Externo | M1: Dados/Sistema | N1: PERÍODO DE REFERÊNCIA | O1: DEADLINE | P1: OBSERVAÇÃO | Q1: Pontos Recebidos 2025 | R1: Pontos Recebidos 2024 | S1: Itens de Medição Parcial GEDAD | T1: FORMULÁRIO | U1: PONTOS APLICÁVEIS | V1: PONTOS ESTIMADOS
A2: 1. GOVERNANÇA | B2: Resolução CNJ nº 219/2016 (priorização do 1º Grau) | C2: 9.I.A | D2: Funções Comissionadas entre 1º e 2º graus | E2: Distribuição dos(as) servidores(as) entre os graus de jurisdição | F2: 20 | G2: =V2 -> 0 | H2: =IFERROR(G2/F2,0) -> 0 | I2: Meales Medeiros de Melo | J2: Fabio Jose de Oliveira Araujo | K2: GEDAD | M2: SRH | N2: SITUAÇÃO EM 30/06/2026 | O2: 46203 | Q2: 20 | R2: 10 | S2: x | T2: =IF(D2=B2,CONCATENATE(A2," - ",B2),CONCATENATE(A2," - ",B2," - ",D2)) -> 1. GOVERNANÇA - Resolução CNJ nº 219/2016 (priorização do 1º Grau) - Funções Comissionadas entre 1º e 2º graus | U2: =F2 -> 20 | V2: =IFERROR(VLOOKUP(T2,'Parcial - Prestação de contas'!A:D,4, ),0) -> 0
A3: 1. GOVERNANÇA | B3: Resolução CNJ nº 219/2016 (priorização do 1º Grau) | C3: 9.I.B | D3: Cargos em Comissão entre 1º e 2º graus | E3: Distribuição dos valores integrais das funções comissionadas entre os graus de jurisdição | F3: 20 | G3: =V3 -> 0 | H3: =IFERROR(G3/F3,0) -> 0 | I3: Meales Medeiros de Melo | J3: Fabio Jose de Oliveira Araujo | K3: GEDAD | M3: SRH | N3: SITUAÇÃO EM 30/06/2026 | O3: 46203 | Q3: 20 | R3: 10 | S3: x | T3: =IF(D3=B3,CONCATENATE(A3," - ",B3),CONCATENATE(A3," - ",B3," - ",D3)) -> 1. GOVERNANÇA - Resolução CNJ nº 219/2016 (priorização do 1º Grau) - Cargos em Comissão entre 1º e 2º graus | U3: =F3 -> 20 | V3: =IFERROR(VLOOKUP(T3,'Parcial - Prestação de contas'!A:D,4, ),0) -> 0
A4: 1. GOVERNANÇA | B4: Resolução CNJ nº 219/2016 (priorização do 1º Grau) | C4: 9.I.C | D4: Quantidade de servidores entre 1º e 2º graus | E4: Distribuição dos valores integrais dos cargos em comissão entre os graus de jurisdição | F4: 20 | G4: =V4 -> 0 | H4: =IFERROR(G4/F4,0) -> 0 | I4: Meales Medeiros de Melo | J4: Fabio Jose de Oliveira Araujo | K4: GEDAD | M4: SRH | N4: SITUAÇÃO EM 30/06/2026 | O4: 46203 | Q4: 0 | R4: 0 | S4: x | T4: =IF(D4=B4,CONCATENATE(A4," - ",B4),CONCATENATE(A4," - ",B4," - ",D4)) -> 1. GOVERNANÇA - Resolução CNJ nº 219/2016 (priorização do 1º Grau) - Quantidade de servidores entre 1º e 2º graus | U4: =F4 -> 20 | V4: =IFERROR(VLOOKUP(T4,'Parcial - Prestação de contas'!A:D,4, ),0) -> 0
A5: 1. GOVERNANÇA | B5: Resolução CNJ nº 219/2016 (priorização do 1º Grau) | C5: 9.I.D | D5: Cargos em comissão da área administrativa | E5: Limite de 30,00% na área de apoio indireto – servidores(as) | F5: 5 | G5: =V5 -> 0 | H5: =IFERROR(G5/F5,0) -> 0 | I5: Meales Medeiros de Melo | J5: Fabio Jose de Oliveira Araujo | K5: GEDAD | M5: SRH | N5: SITUAÇÃO EM 30/06/2026 | O5: 46203 | Q5: 5 | R5: 5 | S5: x | T5: =IF(D5=B5,CONCATENATE(A5," - ",B5),CONCATENATE(A5," - ",B5," - ",D5)) -> 1. GOVERNANÇA - Resolução CNJ nº 219/2016 (priorização do 1º Grau) - Cargos em comissão da área administrativa | U5: =F5 -> 5 | V5: =IFERROR(VLOOKUP(T5,'Parcial - Prestação de contas'!A:D,4, ),0) -> 0
A6: 1. GOVERNANÇA | B6: Resolução CNJ nº 219/2016 (priorização do 1º Grau) | C6: 9.I.E | D6: Funções comissionadas da área administrativa | E6: Limite de 30,00% na área de apoio indireto – funções comissionadas | F6: 5 | G6: =V6 -> 0 | H6: =IFERROR(G6/F6,0) -> 0 | I6: Meales Medeiros de Melo | J6: Fabio Jose de Oliveira Araujo | K6: GEDAD | M6: SRH | N6: SITUAÇÃO EM 30/06/2026 | O6: 46203 | Q6: 5 | R6: 5 | S6: x | T6: =IF(D6=B6,CONCATENATE(A6," - ",B6),CONCATENATE(A6," - ",B6," - ",D6)) -> 1. GOVERNANÇA - Resolução CNJ nº 219/2016 (priorização do 1º Grau) - Funções comissionadas da área administrativa | U6: =F6 -> 5 | V6: =IFERROR(VLOOKUP(T6,'Parcial - Prestação de contas'!A:D,4, ),0) -> 0
A7: 1. GOVERNANÇA | B7: Resolução CNJ nº 219/2016 (priorização do 1º Grau) | C7: 9.I.F | D7: Quantidade de servidores da área administrativa | E7: Limite de 30,00% na área de apoio indireto – cargos em comissão | F7: 5 | G7: =V7 -> 0 | H7: =IFERROR(G7/F7,0) -> 0 | I7: Meales Medeiros de Melo | J7: Fabio Jose de Oliveira Araujo | K7: GEDAD | M7: SRH | N7: SITUAÇÃO EM 30/06/2026 | O7: 46203 | Q7: 5 | R7: 5 | S7: x | T7: =IF(D7=B7,CONCATENATE(A7," - ",B7),CONCATENATE(A7," - ",B7," - ",D7)) -> 1. GOVERNANÇA - Resolução CNJ nº 219/2016 (priorização do 1º Grau) - Quantidade de servidores da área administrativa | U7: =F7 -> 5 | V7: =IFERROR(VLOOKUP(T7,'Parcial - Prestação de contas'!A:D,4, ),0) -> 0
A8: 1. GOVERNANÇA | B8: Resolução CNJ nº 219/2016 (priorização do 1º Grau) | C8: 9.I.G | D8: Orçamento entre 1º e 2º graus | E8: Distribuição do orçamento de natureza não vinculada entre os graus de jurisdição, proporcional à média de casos novos do triênio | F8: 10 | G8: =V8 -> 0 | H8: =IFERROR(G8/F8,0) -> 0 | I8: Meales Medeiros de Melo | J8: Leonardo Sousa de Paiva Oliveira | K8: DIFIN | N8: Lei Orçamentária Anual (LOA) de 2026 | O8: 46022 | Q8: 10 | R8: 10 | T8: =IF(D8=B8,CONCATENATE(A8," - ",B8),CONCATENATE(A8," - ",B8," - ",D8)) -> 1. GOVERNANÇA - Resolução CNJ nº 219/2016 (priorização do 1º Grau) - Orçamento entre 1º e 2º graus | U8: =F8 -> 10 | V8: =IFERROR(VLOOKUP(T8,'Parcial - Prestação de contas'!A:D,4, ),0) -> 0
A9: 1. GOVERNANÇA | B9: Gestão participativa na elaboração das Metas Nacionais | C9: 9.II.A1 | D9: Realizar audiência pública | E9: Realizar consulta pública | F9: 15 | G9: =V9 -> 0 | H9: =IFERROR(G9/F9,0) -> 0 | I9: Meales Medeiros de Melo | J9: Antonieta Lucia Maroja Arcoverde Nobrega | K9: GEPLA | M9: PLANILHA | N9: 01/01/2026 A 31/07/2026 | O9: 46234 | Q9: 15 | R9: 15 | T9: =IF(D9=B9,CONCATENATE(A9," - ",B9),CONCATENATE(A9," - ",B9," - ",D9)) -> 1. GOVERNANÇA - Gestão participativa na elaboração das Metas Nacionais - Realizar audiência pública | U9: =F9 -> 15 | V9: =IFERROR(VLOOKUP(T9,'Parcial - Prestação de contas'!A:D,4, ),0) -> 0
A10: 1. GOVERNANÇA | B10: Gestão participativa na elaboração das Metas Nacionais | C10: 9.II.A2 | D10: Realizar consulta pública | E10: Realizar audiência pública | F10: 15 | G10: =V10 -> 0 | H10: =IFERROR(G10/F10,0) -> 0 | I10: Meales Medeiros de Melo | J10: Antonieta Lucia Maroja Arcoverde Nobrega | K10: GEPLA | M10: PLANILHA | N10: 01/01/2026 A 31/07/2026 | O10: 46234 | Q10: 15 | R10: 0 | T10: =IF(D10=B10,CONCATENATE(A10," - ",B10),CONCATENATE(A10," - ",B10," - ",D10)) -> 1. GOVERNANÇA - Gestão participativa na elaboração das Metas Nacionais - Realizar consulta pública | U10: =F10 -> 15 | V10: =IFERROR(VLOOKUP(T10,'Parcial - Prestação de contas'!A:D,4, ),0) -> 0
A11: 1. GOVERNANÇA | B11: Gestão participativa na elaboração das Metas Nacionais | C11: 9.II.B | D11: Realizar uma ou mais reuniões com Magistrados e servidores | E11: Realizar uma ou mais reuniões com Magistrados e servidores | F11: 30 | G11: =V11 -> 0 | H11: =IFERROR(G11/F11,0) -> 0 | I11: Meales Medeiros de Melo | J11: Antonieta Lucia Maroja Arcoverde Nobrega | K11: GEPLA | M11: PLANILHA | N11: 01/01/2026 A 31/07/2026 | O11: 46234 | Q11: 30 | R11: 30 | T11: =IF(D11=B11,CONCATENATE(A11," - ",B11),CONCATENATE(A11," - ",B11," - ",D11)) -> 1. GOVERNANÇA - Gestão participativa na elaboração das Metas Nacionais - Realizar uma ou mais reuniões com Magistrados e servidores | U11: =F11 -> 30 | V11: =IFERROR(VLOOKUP(T11,'Parcial - Prestação de contas'!A:D,4, ),0) -> 0
A12: 1. GOVERNANÇA | B12: Gestão Socioambiental e IDS | C12: 9.III | D12: Resultado do IDS | E12: Resultado do IDS | F12: 50 | G12: =V12 -> 0 | H12: =IFERROR(G12/F12,0) -> 0 | I12: Meales Medeiros de Melo | J12: Lua Yamaoka Mariz Maia Pitanga | K12: NGSA | M12: PLANILHA | N12: ANO-BASE 2025 | O12: 46022 | Q12: 20 | R12: 15 | T12: =IF(D12=B12,CONCATENATE(A12," - ",B12),CONCATENATE(A12," - ",B12," - ",D12)) -> 1. GOVERNANÇA - Gestão Socioambiental e IDS - Resultado do IDS | U12: =F12 -> 50 | V12: =IFERROR(VLOOKUP(T12,'Parcial - Prestação de contas'!A:D,4, ),0) -> 0
A13: 1. GOVERNANÇA | B13: Judicialização da Saúde | C13: 9.IV.A | D13: Possuir NatJus | E13: Possuir NatJus que realize apoio técnico nas ações de saúde suplementar | F13: 10 | G13: =V13 -> 0 | H13: =IFERROR(G13/F13,0) -> 0 | I13: Meales Medeiros de Melo | J13: Silmary Alves de Queiroga Vita | K13: COMITÊ ESTADUAL DE SAÚDE | M13: PLANILHA | N13: SITUAÇÃO EM 31/07/2026 | O13: 46234 | Q13: 10 | R13: 10 | T13: =IF(D13=B13,CONCATENATE(A13," - ",B13),CONCATENATE(A13," - ",B13," - ",D13)) -> 1. GOVERNANÇA - Judicialização da Saúde - Possuir NatJus | U13: =F13 -> 10 | V13: =IFERROR(VLOOKUP(T13,'Parcial - Prestação de contas'!A:D,4, ),0) -> 0
A14: 1. GOVERNANÇA | B14: Judicialização da Saúde | C14: 9.IV.B | D14: Executar Plano de Estadual | E14: Executar duas ações do Plano Estadual ou Distrital elaborado | F14: 10 | G14: =V14 -> 0 | H14: =IFERROR(G14/F14,0) -> 0 | I14: Meales Medeiros de Melo | J14: Silmary Alves de Queiroga Vita | K14: COMITÊ ESTADUAL DE SAÚDE | M14: PLANILHA | N14: 01/08/2025 A 31/07/2026 | O14: 46234 | Q14: 10 | T14: =IF(D14=B14,CONCATENATE(A14," - ",B14),CONCATENATE(A14," - ",B14," - ",D14)) -> 1. GOVERNANÇA - Judicialização da Saúde - Executar Plano de Estadual | U14: =F14 -> 10 | V14: =IFERROR(VLOOKUP(T14,'Parcial - Prestação de contas'!A:D,4, ),0) -> 0
A15: 1. GOVERNANÇA | B15: Judicialização da Saúde | C15: 9.IV.C | D15: Acordo de Cooperação Técnica | E15: Possuir acordo de cooperação técnica, ou instrumento similar, com entes do SUS ou com operadoras de planos de saúde | F15: 10 | G15: =V15 -> 0 | H15: =IFERROR(G15/F15,0) -> 0 | I15: Meales Medeiros de Melo | J15: Silmary Alves de Queiroga Vita | K15: COMITÊ ESTADUAL DE SAÚDE | M15: PLANILHA | N15: SITUAÇÃO EM 31/07/2026 | O15: 46234 | Q15: 10 | R15: 10 | T15: =IF(D15=B15,CONCATENATE(A15," - ",B15),CONCATENATE(A15," - ",B15," - ",D15)) -> 1. GOVERNANÇA - Judicialização da Saúde - Acordo de Cooperação Técnica | U15: =F15 -> 10 | V15: =IFERROR(VLOOKUP(T15,'Parcial - Prestação de contas'!A:D,4, ),0) -> 0
A16: 1. GOVERNANÇA | B16: Judicialização da Saúde | C16: 9.IV.D | D16: Capacitação | E16: Realizar cursos capacitação com os(as) magistrados(as), voltados ao Direito da Saúde e/ou Judicialização da Saúde | F16: 10 | G16: =V16 -> 0 | H16: =IFERROR(G16/F16,0) -> 0 | I16: Meales Medeiros de Melo | J16: Silmary Alves de Queiroga Vita | K16: ESMA | M16: PLANILHA | N16: 01/08/2025 A 31/07/2026 | O16: 46234 | Q16: 10 | T16: =IF(D16=B16,CONCATENATE(A16," - ",B16),CONCATENATE(A16," - ",B16," - ",D16)) -> 1. GOVERNANÇA - Judicialização da Saúde - Capacitação | U16: =F16 -> 10 | V16: =IFERROR(VLOOKUP(T16,'Parcial - Prestação de contas'!A:D,4, ),0) -> 0
A17: 1. GOVERNANÇA | B17: Judicialização da Saúde | C17: 9.IV.E | D17: Possuir unidade judiciária especializada na temática da saúde | E17: Possuir unidade judiciária especializada na temática da saúde | F17: 10 | G17: =V17 -> 0 | H17: =IFERROR(G17/F17,0) -> 0 | I17: Meales Medeiros de Melo | J17: Silmary Alves de Queiroga Vita | K17: GEDAD | M17: PLANILHA | N17: SITUAÇÃO EM 31/07/2026 | O17: 46234 | Q17: 10 | R17: 10 | T17: =IF(D17=B17,CONCATENATE(A17," - ",B17),CONCATENATE(A17," - ",B17," - ",D17)) -> 1. GOVERNANÇA - Judicialização da Saúde - Possuir unidade judiciária especializada na temática da saúde | U17: =F17 -> 10 | V17: =IFERROR(VLOOKUP(T17,'Parcial - Prestação de contas'!A:D,4, ),0) -> 0
A18: 1. GOVERNANÇA | B18: Centro de Inteligência do Poder Judiciário | C18: 9.V | D18: Emitir 3 Notas técnicas | E18: Emitir 3 Notas técnicas | F18: 15 | G18: =V18 -> 0 | H18: =IFERROR(G18/F18,0) -> 0 | I18: Meales Medeiros de Melo | J18: Jeremias de Cassio Carneiro de Melo | K18: GEPLA | M18: PLANILHA | N18: 01/08/2025 A 31/07/2026 | O18: 46234 | Q18: 15 | R18: 15 | T18: =IF(D18=B18,CONCATENATE(A18," - ",B18),CONCATENATE(A18," - ",B18," - ",D18)) -> 1. GOVERNANÇA - Centro de Inteligência do Poder Judiciário - Emitir 3 Notas técnicas | U18: =F18 -> 15 | V18: =IFERROR(VLOOKUP(T18,'Parcial - Prestação de contas'!A:D,4, ),0) -> 0
A19: 1. GOVERNANÇA | B19: Assédio Moral, Sexual e Discriminação | C19: 9.VI.A | D19: Capacitação de servidores chefes | E19: Realizar campanha de orientação e esclarecimento sobre assédio moral, assédio sexual e discriminação | F19: 10 | G19: =V19 -> 0 | H19: =IFERROR(G19/F19,0) -> 0 | I19: Meales Medeiros de Melo | J19: Tulia Gomes de Souza Neves | K19: COAPO | M19: PLANILHA | N19: 01/08/2025 A 31/07/2026 | O19: 46234 | Q19: 10 | R19: 10 | T19: =IF(D19=B19,CONCATENATE(A19," - ",B19),CONCATENATE(A19," - ",B19," - ",D19)) -> 1. GOVERNANÇA - Assédio Moral, Sexual e Discriminação - Capacitação de servidores chefes | U19: =F19 -> 10 | V19: =IFERROR(VLOOKUP(T19,'Parcial - Prestação de contas'!A:D,4, ),0) -> 0
A20: 1. GOVERNANÇA | B20: Assédio Moral, Sexual e Discriminação | C20: 9.VI.B | D20: Semana de Combate ao Assédio | E20: Possuir o mínimo de 20,00% dos(as) servidores(as) ocupantes de cargo de chefia do órgão capacitados na temática | F20: 10 | G20: =V20 -> 0 | H20: =IFERROR(G20/F20,0) -> 0 | I20: Meales Medeiros de Melo | J20: Tulia Gomes de Souza Neves | K20: ESMA | M20: PLANILHA | N20: 01/01/2022 A 31/07/2026 | O20: 46234 | Q20: 10 | T20: =IF(D20=B20,CONCATENATE(A20," - ",B20),CONCATENATE(A20," - ",B20," - ",D20)) -> 1. GOVERNANÇA - Assédio Moral, Sexual e Discriminação - Semana de Combate ao Assédio | U20: =F20 -> 10 | V20: =IFERROR(VLOOKUP(T20,'Parcial - Prestação de contas'!A:D,4, ),0) -> 0
A21: 1. GOVERNANÇA | B21: Assédio Moral, Sexual e Discriminação | C21: 9.VI.C | D21: Campanha de orientação | E21: Realizar a semana de combate ao assédio no mês de maio(magistrados(as), servidores(as) e quadro auxiliar) (10 pontos); | F21: 10 | G21: =V21 -> 0 | H21: =IFERROR(G21/F21,0) -> 0 | I21: Meales Medeiros de Melo | J21: Tulia Gomes de Souza Neves | K21: COAPO | M21: PLANILHA | N21: MAIO DE 2026 | O21: 46173 | Q21: 10 | R21: 10 | T21: =IF(D21=B21,CONCATENATE(A21," - ",B21),CONCATENATE(A21," - ",B21," - ",D21)) -> 1. GOVERNANÇA - Assédio Moral, Sexual e Discriminação - Campanha de orientação | U21: =F21 -> 10 | V21: =IFERROR(VLOOKUP(T21,'Parcial - Prestação de contas'!A:D,4, ),0) -> 0
A22: 1. GOVERNANÇA | B22: Assédio Moral, Sexual e Discriminação | C22: 9.VI.D | D22: Penquisa que avalie assédio no tribunal | E22: Ter realizado pelo menos uma pesquisa interna que avalie o assédio no tribunal | F22: 10 | G22: =V22 -> 0 | H22: =IFERROR(G22/F22,0) -> 0 | I22: Meales Medeiros de Melo | J22: Tulia Gomes de Souza Neves | K22: COAPO | M22: PLANILHA | N22: 01/01/2023 A 31/07/2026 | O22: 46234 | Q22: 10 | T22: =IF(D22=B22,CONCATENATE(A22," - ",B22),CONCATENATE(A22," - ",B22," - ",D22)) -> 1. GOVERNANÇA - Assédio Moral, Sexual e Discriminação - Penquisa que avalie assédio no tribunal | U22: =F22 -> 10 | V22: =IFERROR(VLOOKUP(T22,'Parcial - Prestação de contas'!A:D,4, ),0) -> 0
A23: 1. GOVERNANÇA | B23: Gestão de Memória e Documental | C23: 9.VII.A | D23: Ambientes físicos e virtuais de preservação da memória | E23: Publicação de pelo menos dois editais de eliminação | F23: 20 | G23: =V23 -> 0 | H23: =IFERROR(G23/F23,0) -> 0 | I23: Meales Medeiros de Melo | J23: Fabio Jose de Oliveira Araujo | K23: CPAD | M23: PLANILHA | N23: 01/08/2025 A 31/07/2026 | O23: 46234 | Q23: 20 | R23: 20 | T23: =IF(D23=B23,CONCATENATE(A23," - ",B23),CONCATENATE(A23," - ",B23," - ",D23)) -> 1. GOVERNANÇA - Gestão de Memória e Documental - Ambientes físicos e virtuais de preservação da memória | U23: =F23 -> 20 | V23: =IFERROR(VLOOKUP(T23,'Parcial - Prestação de contas'!A:D,4, ),0) -> 0
A24: 1. GOVERNANÇA | B24: Gestão de Memória e Documental | C24: 9.VII.B | D24: Editais de eliminação | E24: Possuir ambientes físicos e virtuais de preservação da memória | F24: 10 | G24: =V24 -> 0 | H24: =IFERROR(G24/F24,0) -> 0 | I24: Meales Medeiros de Melo | J24: Fabio Jose de Oliveira Araujo | K24: CPAD | M24: PLANILHA | N24: SITUAÇÃO EM 31/07/2026 | O24: 46234 | Q24: 10 | R24: 10 | T24: =IF(D24=B24,CONCATENATE(A24," - ",B24),CONCATENATE(A24," - ",B24," - ",D24)) -> 1. GOVERNANÇA - Gestão de Memória e Documental - Editais de eliminação | U24: =F24 -> 10 | V24: =IFERROR(VLOOKUP(T24,'Parcial - Prestação de contas'!A:D,4, ),0) -> 0
A25: 1. GOVERNANÇA | B25: Política Nacional de Justiça Restaurativa | C25: 9.VIII.A | D25: Possuir CEJURE | E25: Possuir pelo menos um Núcleo de Justiça Restaurativa estruturado que contenha, no mínimo, dois servidores(as) com dedicação exclusiva e capacitados(as) como facilitadores(as) em práticas restaurativas | F25: 10 | G25: =V25 -> 0 | H25: =IFERROR(G25/F25,0) -> 0 | I25: Meales Medeiros de Melo | J25: Ivna Mozart Bezerra Soares | K25: NEJURE | M25: PLANILHA | N25: SITUAÇÃO EM 31/07/2026 | O25: 46234 | Q25: 10 | R25: 10 | T25: =IF(D25=B25,CONCATENATE(A25," - ",B25),CONCATENATE(A25," - ",B25," - ",D25)) -> 1. GOVERNANÇA - Política Nacional de Justiça Restaurativa - Possuir CEJURE | U25: =F25 -> 10 | V25: =IFERROR(VLOOKUP(T25,'Parcial - Prestação de contas'!A:D,4, ),0) -> 0
A26: 1. GOVERNANÇA | B26: Política Nacional de Justiça Restaurativa | C26: 9.VIII.B | D26: Capacitação | E26: Realizar capacitação, na teoria e prática da Justiça Restaurativa, nos termos do Plano Pedagógico Mínimo Orientador para Formações em Justiça Restaurativa | F26: 20 | G26: =V26 -> 0 | H26: =IFERROR(G26/F26,0) -> 0 | I26: Meales Medeiros de Melo | J26: Ivna Mozart Bezerra Soares | K26: NEJURE | M26: PLANILHA | N26: 01/08/2025 A 31/07/2026 | O26: 46234 | Q26: 20 | R26: 20 | T26: =IF(D26=B26,CONCATENATE(A26," - ",B26),CONCATENATE(A26," - ",B26," - ",D26)) -> 1. GOVERNANÇA - Política Nacional de Justiça Restaurativa - Capacitação | U26: =F26 -> 20 | V26: =IFERROR(VLOOKUP(T26,'Parcial - Prestação de contas'!A:D,4, ),0) -> 0
A27: 1. GOVERNANÇA | B27: Política Nacional de Justiça Restaurativa | C27: 9.VIII.C | D27: Relatório de Atividades | E27: Relatório de atividades do Núcleo de Justiça Restaurativa | F27: 10 | G27: =V27 -> 0 | H27: =IFERROR(G27/F27,0) -> 0 | I27: Meales Medeiros de Melo | J27: Ivna Mozart Bezerra Soares | K27: NEJURE | M27: PLANILHA | N27: 01/08/2025 A 31/07/2026 | O27: 46234 | Q27: 10 | R27: 10 | T27: =IF(D27=B27,CONCATENATE(A27," - ",B27),CONCATENATE(A27," - ",B27," - ",D27)) -> 1. GOVERNANÇA - Política Nacional de Justiça Restaurativa - Relatório de Atividades | U27: =F27 -> 10 | V27: =IFERROR(VLOOKUP(T27,'Parcial - Prestação de contas'!A:D,4, ),0) -> 0
A28: 1. GOVERNANÇA | B28: Instalar GMF | C28: 9.IX.A.EB | D28: Estrutura de apoio administrativo / Equipe multiprofissional | E28: Estrutura de apoio administrativo / Equipe multiprofissional | F28: 20 | G28: =V28 -> 0 | H28: =IFERROR(G28/F28,0) -> 0 | I28: Meales Medeiros de Melo | J28: Maria Aparecida Sarmento Gadelha | K28: GMF | M28: PLANILHA | N28: SITUAÇÃO EM 31/07/2026 | O28: 46234 | Q28: 20 | R28: 20 | T28: =IF(D28=B28,CONCATENATE(A28," - ",B28),CONCATENATE(A28," - ",B28," - ",D28)) -> 1. GOVERNANÇA - Instalar GMF - Estrutura de apoio administrativo / Equipe multiprofissional | U28: =F28 -> 20 | V28: =IFERROR(VLOOKUP(T28,'Parcial - Prestação de contas'!A:D,4, ),0) -> 0
A29: 1. GOVERNANÇA | B29: Inspeções nos estabelecimentos penais | C29: 9.X | D29: Inspeções nos estabelecimentos penais | E29: Inspeções nos estabelecimentos penais | F29: 30 | G29: =V29 -> 0 | H29: =IFERROR(G29/F29,0) -> 0 | I29: Meales Medeiros de Melo | J29: Maria Aparecida Sarmento Gadelha | K29: UNIDADES JUDICIÁRIAS | L29: X | M29: CNIEPS | N29: 01/09/2025 A 31/08/2026 | O29: 46265 | Q29: 0 | R29: 0 | S29: x | T29: =IF(D29=B29,CONCATENATE(A29," - ",B29),CONCATENATE(A29," - ",B29," - ",D29)) -> 1. GOVERNANÇA - Inspeções nos estabelecimentos penais | U29: =F29 -> 30 | V29: =IFERROR(VLOOKUP(T29,'Parcial - Prestação de contas'!A:D,4, ),0) -> 0
A30: 1. GOVERNANÇA | B30: Inspeções nos estabelecimentos de medidas socioeducativas | C30: 9.XI.A | D30: Meio Fechado | E30: Meio Fechado | F30: 20 | G30: =V30 -> 0 | H30: =IFERROR(G30/F30,0) -> 0 | I30: Meales Medeiros de Melo | J30: Antonieta Lucia Maroja Arcoverde Nobrega | K30: UNIDADES JUDICIÁRIAS | L30: X | M30: CNIUPS | N30: 01/07/2025 A 30/06/2026 | O30: 46203 | Q30: 20 | R30: 20 | S30: x | T30: =IF(D30=B30,CONCATENATE(A30," - ",B30),CONCATENATE(A30," - ",B30," - ",D30)) -> 1. GOVERNANÇA - Inspeções nos estabelecimentos de medidas socioeducativas - Meio Fechado | U30: =F30 -> 20 | V30: =IFERROR(VLOOKUP(T30,'Parcial - Prestação de contas'!A:D,4, ),0) -> 0
A31: 1. GOVERNANÇA | B31: Inspeções nos estabelecimentos de medidas socioeducativas | C31: 9.XI.B | D31: Meio aberto | E31: Meio aberto | F31: 10 | G31: =V31 -> 0 | H31: =IFERROR(G31/F31,0) -> 0 | I31: Meales Medeiros de Melo | J31: Antonieta Lucia Maroja Arcoverde Nobrega | K31: UNIDADES JUDICIÁRIAS | L31: X | M31: CNIUPS | N31: 01/07/2025 A 30/06/2026 | O31: 46203 | Q31: 10 | R31: 10 | S31: x | T31: =IF(D31=B31,CONCATENATE(A31," - ",B31),CONCATENATE(A31," - ",B31," - ",D31)) -> 1. GOVERNANÇA - Inspeções nos estabelecimentos de medidas socioeducativas - Meio aberto | U31: =F31 -> 10 | V31: =IFERROR(VLOOKUP(T31,'Parcial - Prestação de contas'!A:D,4, ),0) -> 0
A32: 1. GOVERNANÇA | B32: Participação Institucional Feminina | C32: 9.XII.A | D32: Paridade na promoção por merecimento | E32: Paridade de gênero nas promoções por merecimento do primeiro para o segundo grau; ou paridade no total de desembargadoras ativas e que tenham ingressado pelo critério de merecimento | F32: 10 | G32: =V32 -> 0 | H32: =IFERROR(G32/F32,0) -> 0 | I32: Meales Medeiros de Melo | J32: Maria Aparecida Sarmento Gadelha | K32: TRIBUNAL PLENO | M32: PLANILHA | N32: 01/08/2025 A 31/07/2026 | O32: 46234 | Q32: 10 | R32: 0 | T32: =IF(D32=B32,CONCATENATE(A32," - ",B32),CONCATENATE(A32," - ",B32," - ",D32)) -> 1. GOVERNANÇA - Participação Institucional Feminina - Paridade na promoção por merecimento | U32: =F32 -> 10 | V32: =IFERROR(VLOOKUP(T32,'Parcial - Prestação de contas'!A:D,4, ),0) -> 0
A33: 1. GOVERNANÇA | B33: Participação Institucional Feminina | C33: 9.XII.C | D33: Paridade magistradas auxiliares | E33: Percentual paritário de magistradas designadas como auxiliares para cargos na alta administração do Poder Judiciário (juíza auxiliar da presidência, vice-presidência e corregedoria; diretora de escolas judiciais; diretora de foro de seção judiciária; e ouvidora, inclusive ouvidora da mulher) | F33: 10 | G33: =V33 -> 0 | H33: =IFERROR(G33/F33,0) -> 0 | I33: Meales Medeiros de Melo | J33: Maria Aparecida Sarmento Gadelha | K33: PRESIDÊNCIA | M33: SRH | N33: SITUAÇÃO EM 31/07/2026 | O33: 46234 | Q33: 0 | R33: 0 | T33: =IF(D33=B33,CONCATENATE(A33," - ",B33),CONCATENATE(A33," - ",B33," - ",D33)) -> 1. GOVERNANÇA - Participação Institucional Feminina - Paridade magistradas auxiliares | U33: =F33 -> 10 | V33: =IFERROR(VLOOKUP(T33,'Parcial - Prestação de contas'!A:D,4, ),0) -> 0
A34: 1. GOVERNANÇA | B34: Participação Institucional Feminina | C34: 9.XII.D | D34: Paridade cortes eleitorais | E34: Percentual paritário de magistradas designadas para compor as cortes eleitorais | F34: 10 | G34: =V34 -> 0 | H34: =IFERROR(G34/F34,0) -> 0 | I34: Meales Medeiros de Melo | J34: Maria Aparecida Sarmento Gadelha | K34: TRIBUNAL PLENO | M34: PLANILHA | N34: 01/08/2025 A 31/07/2026 | O34: 46234 | Q34: 0 | R34: 10 | T34: =IF(D34=B34,CONCATENATE(A34," - ",B34),CONCATENATE(A34," - ",B34," - ",D34)) -> 1. GOVERNANÇA - Participação Institucional Feminina - Paridade cortes eleitorais | U34: =F34 -> 10 | V34: =IFERROR(VLOOKUP(T34,'Parcial - Prestação de contas'!A:D,4, ),0) -> 0
A35: 1. GOVERNANÇA | B35: Participação Institucional Feminina | C35: 9.XII.E | D35: Paridade servidoras ocupantes de cargos de chefia | E35: Percentual paritário de servidoras ocupantes de cargo de chefia | F35: 10 | G35: =V35 -> 0 | H35: =IFERROR(G35/F35,0) -> 0 | I35: Meales Medeiros de Melo | J35: Maria Aparecida Sarmento Gadelha | K35: GEDAD | M35: SRH | N35: SITUAÇÃO EM 31/07/2026 | O35: 46234 | Q35: 10 | R35: 10 | T35: =IF(D35=B35,CONCATENATE(A35," - ",B35),CONCATENATE(A35," - ",B35," - ",D35)) -> 1. GOVERNANÇA - Participação Institucional Feminina - Paridade servidoras ocupantes de cargos de chefia | U35: =F35 -> 10 | V35: =IFERROR(VLOOKUP(T35,'Parcial - Prestação de contas'!A:D,4, ),0) -> 0
A36: 1. GOVERNANÇA | B36: Apoio às Vítimas de Crimes e Atos Infracionais | C36: 9.XIII | D36: Centros Especializados de Atenção às Vítimas | E36: Existência de Centros Especializados de Atenção às Vítimas em funcionamento e estruturado com equipe multiprofissional. | F36: 20 | G36: =V36 -> 0 | H36: =IFERROR(G36/F36,0) -> 0 | I36: Meales Medeiros de Melo | J36: Maria Aparecida Sarmento Gadelha | K36: UNIDADES JUDICIÁRIAS | M36: PLANILHA | N36: 01/08/2025 A 31/07/2026 | O36: 46234 | Q36: 20 | R36: 20 | T36: =IF(D36=B36,CONCATENATE(A36," - ",B36),CONCATENATE(A36," - ",B36," - ",D36)) -> 1. GOVERNANÇA - Apoio às Vítimas de Crimes e Atos Infracionais - Centros Especializados de Atenção às Vítimas | U36: =F36 -> 20 | V36: =IFERROR(VLOOKUP(T36,'Parcial - Prestação de contas'!A:D,4, ),0) -> 0
A37: 1. GOVERNANÇA | B37: Acessibilidade e inclusão de pessoas com deficiência | C37: 9.XIV.A1 | D37: Eventos realizados | E37: Acessibilidade comunicacional: possuir 70,00% ou mais de eventos realizados com acessibilidade comunicacional, calculado pela relação (QEAc / QEt), conforme indicador 3.4 do anexo da referida resolução | F37: 10 | G37: =V37 -> 0 | H37: =IFERROR(G37/F37,0) -> 0 | I37: Meales Medeiros de Melo | J37: Fabio Jose de Oliveira Araujo | K37: CERIMONIAL/NGSA | M37: PLANILHA | N37: 01/01/2025 A 31/12/2025 | O37: 46022 | Q37: 10 | R37: 10 | T37: =IF(D37=B37,CONCATENATE(A37," - ",B37),CONCATENATE(A37," - ",B37," - ",D37)) -> 1. GOVERNANÇA - Acessibilidade e inclusão de pessoas com deficiência - Eventos realizados | U37: =F37 -> 10 | V37: =IFERROR(VLOOKUP(T37,'Parcial - Prestação de contas'!A:D,4, ),0) -> 0
A38: 1. GOVERNANÇA | B38: Acessibilidade e inclusão de pessoas com deficiência | C38: 9.XIV.A2 | D38: Recursos de tecnologia assistida para srvidores com deficiência visual | E38: Acessibilidade tecnológica: 5 pontos para cada recurso de tecnologia assistida que permita o uso de computadores por pessoas com deficiência visual - resolução | F38: 10 | G38: =V38 -> 0 | H38: =IFERROR(G38/F38,0) -> 0 | I38: Meales Medeiros de Melo | J38: Max Nunes de Franca | K38: DITEC | M38: PLANILHA | N38: ANO-BASE 2025 | O38: 46022 | Q38: 10 | R38: 10 | T38: =IF(D38=B38,CONCATENATE(A38," - ",B38),CONCATENATE(A38," - ",B38," - ",D38)) -> 1. GOVERNANÇA - Acessibilidade e inclusão de pessoas com deficiência - Recursos de tecnologia assistida para srvidores com deficiência visual | U38: =F38 -> 10 | V38: =IFERROR(VLOOKUP(T38,'Parcial - Prestação de contas'!A:D,4, ),0) -> 0
A39: 1. GOVERNANÇA | B39: Acessibilidade e inclusão de pessoas com deficiência | C39: 9.XIV.A.3.2 | D39: Servidores capacitados(as) | E39: Percentual de servidores(as) capacitados(as) nas temáticas de acessibilidade e inclusão das pessoas com deficiência igual ou maior que 10,00%, calculado pela relação: ((QS1 + QS2) / Serv) | F39: 5 | G39: =V39 -> 0 | H39: =IFERROR(G39/F39,0) -> 0 | I39: Meales Medeiros de Melo | J39: Antonieta Lucia Maroja Arcoverde Nobrega | K39: ESMA/NGSA | M39: PLANILHA | N39: ANO-BASE 2025 | O39: 46022 | Q39: 0 | R39: 0 | T39: =IF(D39=B39,CONCATENATE(A39," - ",B39),CONCATENATE(A39," - ",B39," - ",D39)) -> 1. GOVERNANÇA - Acessibilidade e inclusão de pessoas com deficiência - Servidores capacitados(as) | U39: =F39 -> 5 | V39: =IFERROR(VLOOKUP(T39,'Parcial - Prestação de contas'!A:D,4, ),0) -> 0
A40: 1. GOVERNANÇA | B40: Acessibilidade e inclusão de pessoas com deficiência | D40: Relatório de Ações da COMPACI | E40: Relatório de Ações da COMPACI que evidencie os seguintes temas: Acessibilidade Comunicacional, Acessibilidade tecnológica e Capacitação dos Servidores | G40: =V40 -> 0 | I40: Meales Medeiros de Melo | J40: Anna Carla Lopes Correia Lima de Freitas | K40: COAPO | M40: PLANILHA | N40: ANO-BASE 2025 | O40: 46022 | R40: 0 | T40: =IF(D40=B40,CONCATENATE(A40," - ",B40),CONCATENATE(A40," - ",B40," - ",D40)) -> 1. GOVERNANÇA - Acessibilidade e inclusão de pessoas com deficiência - Relatório de Ações da COMPACI | U40: =F40 | V40: =IFERROR(VLOOKUP(T40,'Parcial - Prestação de contas'!A:D,4, ),0) -> 0
...

Sheet Parcial - Prestação de contas
A1: COLAR AQUI | D1: PONTOS ESTIMADOS
A2: 2. PRODUTIVIDADE - Cumprimento das Metas Nacionais - Meta 1 | B2: CUMPRIDO OU EM CUMPRIMENTO | C2: Não se aplica | D2: =IF(B2="PARCIALMENTE CUMPRIDO",C2,IF(B2="NÃO CUMPRIDO",0,VLOOKUP(A2,BD!T:U,2,))) -> 20
A3: 2. PRODUTIVIDADE - Incidentes de progressão de regime | B3: NÃO CUMPRIDO | C3: Não se aplica | D3: =IF(B3="PARCIALMENTE CUMPRIDO",C3,IF(B3="NÃO CUMPRIDO",0,VLOOKUP(A3,BD!T:U,2,))) -> 0
A4: 2. PRODUTIVIDADE - Redução da Taxa de Congestionamento Líquida - Taxa de Congestionamento Líquida | B4: PARCIALMENTE CUMPRIDO | C4: 35 | D4: =IF(B4="PARCIALMENTE CUMPRIDO",C4,IF(B4="NÃO CUMPRIDO",0,VLOOKUP(A4,BD!T:U,2,))) -> 35

Sheet Juizes
A1: Pedro Davi Alves de Vasconcelos
A2: Jeremias de Cassio Carneiro de Melo
A3: Meales Medeiros de Melo
A4: Anderley Ferreira Marques
A5: Alirio Maciel Lima de Brito
A6: Max Nunes de Franca
A7: Maria Aparecida Sarmento Gadelha
A8: Andrea Arcoverde Cavalcanti Vaz
A9: Silmary Alves de Queiroga Vita
A10: Leonardo Sousa de Paiva Oliveira
A11: Jailson Shizue Suassuna
A12: Graziela Queiroga Gadelha de Sousa
... A31: Paula Frassinetti V. de Andrade
